Workbook

Sheet שמות עצםP
B1: תעתיק | C1: פירוש | D1: הקשר | E1: ערבית | F1: גוף | G1: זכר/נקבה | H1: יחיד/רבים | I1: צורת ז/נ | J1: צורת ר/י | K1: נושא | L1: דוגמא | M1: דוגמא 2
A2: 1 | B2: אַצֵל | C2: מקור | H2: י | L2: אנא אצלי מן אלקודס | M2: בלאצל אנא מן תל אביב
A3: 2 | B3: דוֹלֵה | C3: מדינה | H3: י
A4: 3 | B4: בָּלָָד | C4: ארץ/עיר | H4: י
A5: 4 | B5: מָנְטִיקָה | C5: אזור | H5: י
A6: 5 | B6: שָמָאל | C6: צפון | H6: י
A7: 6 | B7: גָ'נוּב | C7: דרום | H7: י
A8: 7 | B8: עָ'רְב | C8: מערב | H8: י
A9: 8 | B9: שָרְק | C9: מזרח | H9: י
A10: 9 | B10: דָאר | C10: בית | H10: י
A11: 10 | B11: שָאי | C11: תה | H11: י
A12: 11 | B12: בִּנְת | C12: בת | G12: נ | H12: י | J12: 12
A13: 12 | B13: בּנָאת | C13: בנות | G13: נ | H13: ר | J13: 11
A14: 13 | B14: קִטָאר | C14: רכבת | H14: י
A15: 14 | B15: תְרֵן | C15: רכבת | H15: י
A16: 15 | B16: חֻכּוּמֵה | C16: ממשלה | G16: נ | H16: י
A17: 16 | B17: וָלָד | C17: ילד | G17: ז | H17: י | J17: 17
A18: 17 | B18: וֻלָאד | C18: ילדים | G18: ז | H18: ר | J18: 16
A19: 18 | B19: בָּרָכֵּה | C19: ברכה | G19: נ | H19: י
A20: 19 | B20: חָרָכֵּה | C20: תנועה | G20: נ | H20: י
A21: 20 | B21: וָרְדָה | C21: פרח | H21: י
A22: 21 | B22: שָרָף | C22: כבוד | G22: ז | H22: י
A23: 22 | B23: שֻעֻ'ל | C23: עבודה | G23: ז | H23: י
A24: 23 | B24: מֻסְתָשְפָא | C24: בית חולים | G24: ז | H24: י
A25: 24 | B25: אִגֵ'ר | C25: רגל | G25: ז | H25: י
A26: 25 | B26: בָּצָל | C26: בצל | G26: ז | H26: י
A27: 26 | B27: חָ'ס | C27: חסה | H27: י
A28: 27 | B28: גָ'זָר | C28: גזר | H28: י
A29: 28 | B29: תוּת | C29: תות
A30: 29 | B30: לָיְמוּן | C30: לימון
A31: 30 | B31: חֻ'דְרָא | C31: ירקות | H31: ר
A32: 31 | B32: פָוָאכֵּה | C32: פירות | H32: ר
A33: 32 | B33: מֻצמֵם | C33: מעצב | G33: ז | H33: י
A34: 33 | B34: מֻצָמִמֵה | C34: מעצבת | G34: נ | H34: י
A35: 34 | B35: מֻדִיר | C35: מנהל | G35: ז | H35: י | I35: 35
A36: 35 | B36: מֻדִירָה | C36: מנהלת | G36: נ | H36: י | I36: 34
A37: 36 | B37: מֻעָאלֵג' | C37: מטפל | G37: ז | H37: י | I37: 37
A38: 37 | B38: מֻעָאלִגֵ'ה | C38: מטפלת | G38: נ | H38: י | I38: 36
A39: 38 | B39: מֻדָלִכּ | C39: מעסֵה | G39: ז | H39: י | I39: 39
A40: 39 | B40: מֻדָלִכֵּה | C40: מעסָה | G40: נ | H40: י | I40: 38
...

Sheet שמות תוארP
B1: תעתיק | C1: פירוש | D1: הקשר | E1: ערבית | F1: זכר/נקבה | G1: יחיד/רבים | H1: צורת ז/נ | I1: צורת ר/י | J1: נושא | K1: דוגמא | L1: דוגמא 2
A2: 1 | B2: מִתְגָ'וֵז | C2: נשוי | F2: ז | G2: י | H2: 2
A3: 2 | B3: מִתְגָ'וְזֵה | C3: נשואה | F3: נ | G3: י | H3: 1
A4: 3 | B4: מְנִיח | C4: טוב
A5: 4 | B5: בָּעִיד | C5: רחוק
A6: 5 | B6: קָרִיב | C6: קרוב
A7: 6 | B7: צָעֵבּ | C7: קשה
A8: 7 | B8: סִהֵל | C8: קל
A9: 8 | B9: מֻתִ'יר | C9: מעניין
A10: 9 | B10: מֻתְעִבּ | C10: מעייף
A11: 10 | B11: מֻמְתָאז | C11: מצויין
A12: 11 | B12: מֻשָוֵק | C12: מרתק
A13: 12 | B13: מֻזְעִג' | C13: מעצבן
A14: 13 | B14: כְּבִּיר | C14: גדול | F14: ז | G14: י | H14: 14
A15: 14 | B15: כְּבִּירֵה | C15: גדולה | F15: נ | G15: י | H15: 13
A16: 15 | B16: כְּבָּאר | C16: גדולים | G16: ר | I16: 13
A17: 16 | B17: זְעִ'יר | C17: קטן | F17: ז | G17: י | H17: 17
A18: 17 | B18: זְעִ'ירֵה | C18: קטנה | F18: נ | G18: י | H18: 16
A19: 18 | B19: זְעָ'אר | C19: קטנים | G19: ר | I19: 16
A20: 19 | B20: כְּתִיר | C20: הרבה
A21: 20 | B21: גֻ'עָאן | C21: רעב | F21: ז | G21: י | H21: 21
A22: 21 | B22: גֻ'עָאנֵה | C22: רעבה | F22: נ | G22: י | H22: 20
A23: 22 | B23: גֻ'עָאנִין | C23: רעבים | G23: ר | I23: 20
A24: 23 | B24: עָטְשָאן | C24: צמא | F24: ז | G24: י | H24: 24
A25: 24 | B25: עָטְשָאנֵה | C25: צמאה | F25: נ | G25: י | H25: 23
A26: 25 | B26: זָאכִּי | C26: טעים
A27: 26 | B27: נָבָּאתִי | C27: צמחוני
A28: 27 | B28: ח'וּדָרִי | C28: טבעוני
A29: 28 | B29: צֵחִּי | C29: בריא
A30: 29 | B30: טָבִּיעִי | C30: טבעי
A31: 30 | B31: זָעְלָאן | C31: כועס
A32: 31 | B32: עָ'אלִי | C32: יקר
A33: 32 | B33: אָעְ'לָא | C33: הכי יקר
A34: 33 | B34: גָ'מִיל | C34: יפה
A35: 34 | B35: אָגְ'מָל | C35: הכי יפה
A36: 35 | B36: חָסָן | C36: חזק
A37: 36 | B37: אָחְסָן | C37: הכי חזק
... A46: 45 | B46: בָּסִיט | C46: פשוט
A47: 46 | B47: מָרִיצ' | C47: חולֵה | F47: ז | G47: י | H47: 47
A48: 47 | B48: מָרִיצָ'ה | C48: חולָה | F48: נ | G48: י | H48: 46
...

Sheet מילות יחסP
B1: תעתיק | C1: פירוש | D1: הקשר | E1: ערבית | F1: נושא | G1: דוגמא | H1: דוגמא 2
A2: 1 | B2: עָן | C2: על | D2: about
A3: 2 | B3: וָרָא | C3: מאחורי
A4: 3 | B4: גָ'נְבּ | C4: ליד
A5: 4 | B5: תָבָּע | C5: של
A6: 5 | B6: וִלָא | C6: או
A7: 6 | B7: אָוְ | C7: או
A8: 7 | B8: מָעָ | C8: עם
A9: 8 | B9: עָשָאן | C9: כי
A10: 9 | B10: עָשָאן | C10: כדי
A11: 10 | B11: אִנִי | C11: שאני
A12: 11 | B12: אִנָכּ | C12: שאתה
A13: 12 | B13: אִנֵכּ | C13: שאת
A14: 13 | B14: אִנוֹ | C14: שהוא
... A23: 22 | B23: לָאִנּוֹ | C23: כי

Sheet מילות שאלהP
B1: תעתיק | C1: פירוש | D1: הקשר | E1: ערבית | F1: זכר/נקבה | G1: נושא | H1: דוגמא | I1: דוגמא 2
A2: 1 | B2: שוּ | C2: מה
A3: 2 | B3: אֵיש | C3: מה
A4: 3 | B4: לֵיש | C4: למה
A5: 4 | B5: כִּיף | C5: איך
A6: 5 | B6: וֵין | C6: איפה
A7: 6 | B7: קָדֵיש | C7: כמה | D7: לכמות לא ספירה
A8: 7 | B8: אָכָּם | C8: כמה | D8: לכמות ספירה
A9: 8 | B9: אֵימְתָא | C9: מתי
A10: 9 | B10: אָנוּ | C10: איזה | F10: ז
A11: 10 | B11: אָנִי | C11: איזה | F11: נ

Sheet ביטוייםP
B1: תעתיק | C1: פירוש | D1: הקשר | E1: ערבית | F1: גוף | G1: זכר/נקבה | H1: יחיד/רבים | I1: צורת ז/נ | J1: צורת ר/י | K1: נושא | L1: דוגמא | M1: דוגמא 2
A2: 1 | B2: כֻּל אֵלְאִחְתִרָאם | C2: כל הכבוד
A3: 2 | B3: אֵ(ל)צָרָאחָה | C3: האמת
A4: 3 | B4: חָאדֵר | C4: כבר מוכן
A5: 4 | B5: נָעִימָן | C5: תתחדש/י | D5: אחרי תספורת/גילוח/מקלחת
A6: 5 | B6: צָחָה | C6: לבריאות
A7: 6 | B7: שֻכְּרָן | C7: תודה
A8: 7 | B8: עָפְוָן | C8: בבקשה
A9: 8 | B9: הֵיכּ | C9: ככה
A10: 9 | B10: אִעְמֵל מָעְרוּף | C10: תעשה טובה
A11: 10 | B11: שוּ מָאלוֹ | C11: מה יש לו
A12: 11 | B12: עָלָא רָאחְתִי | C12: במנוחה
A13: 12 | B13: עָלָא אֵלְאָקָל | C13: לפחות | D13: לכל הפחות
A14: 13 | B14: אָאְסֵף | C14: מצטער | F14: אני
A15: 14 | B15: בָּסִיטָה | C15: בקטנה
A16: 15 | B16: וּחְיָאת רָבִּי | C16: בחיי
A17: 16 | B17: עָן גָ'ד | C17: ברצינות
A18: 17 | B18: כֻּל אִישִי | C18: הכל
A19: 18 | B19: וָלָא אִישִי | C19: כלום
A20: 19 | B20: אָגָ'אכּ | C20: הולך | D20: אני מסכים (סלנג)
A21: 20 | B21: חָאצֵ'ר | C21: אין בעיה | D21: אני מסכים (סלנג)
A22: 21 | B22: בְּסֻרְעָה | C22: מהר | D22: במהירות
A23: 22 | B23: לָחָאלוֹ | C23: לבדו
A24: 23 | B24: מָרָאת | C24: לפעמים
A25: 24 | B25: גָ'אי עָ-בָּאלִי | C25: בא לי
A26: 25 | B26: אָעָ'לְבָּכּ | C26: אפשר לבקש ממך
A27: 26 | B27: בִּלְמָרָה | C27: בכלל לא
A28: 27 | B28: הָאדָא הֻוֵ | C28: זהו זה
A29: 28 | B29: טָבְּעָן | C29: כמובן
A30: 29 | B30: אִנְתֵ אלתָּאנִי | C30: גם כן אתה
A31: 30 | B31: הֵיכּ אִישִי | C31: משהו כזה
A32: 31 | B32: חָ'לִּיכּ פִי חָאלָכּ | C32: אל תתערב
A33: 32 | B33: לֵיש קָאלֵבּ בּוּזָכּ | C33: למה אתה מצוברח
A34: 33 | B34: אִישִי זָיְ הֵיכּ | C34: משהו כזה
A35: 34 | B35: אָכִּיד | C35: בוודאי
A36: 35 | B36: מָעוֹ חָק | C36: הוא צודק | D36: איתו הצדק

Sheet שונותP
B1: תעתיק | C1: פירוש | D1: הקשר | E1: ערבית | F1: גוף | G1: סוג | H1: זכר/נקבה | I1: יחיד/רבים | J1: צורת ז/נ | K1: צורת ר/י | L1: נושא | M1: דוגמא | N1: דוגמא 2
A2: 1 | B2: בֻּכְּרָא | C2: מחר
A3: 2 | B3: לֻבְּנָאן | C3: לבנון
A4: 3 | B4: כֻּל | C4: כל
A5: 4 | B5: מָעְקוּל | C5: הגיוני
A6: 5 | B6: צֵיף | C6: קיץ
A7: 6 | B7: מִתְאָחֵ'ר | C7: מאחר
A8: 7 | B8: לָאבֵּס | C8: לבוש
A9: 8 | B9: בָּרָא | C9: חוץ
A10: 9 | B10: גֻ'וָא | C10: פנים
A11: 10 | B11: אָפְרִיקְיָא | C11: אפריקה
A12: 11 | B12: אִמְבָּארֵח | C12: אתמול
A13: 12 | B13: חָ'רִיף | C13: סתיו
A14: 13 | B14: רָבִּיע | C14: אביב
A15: 14 | C15: חורף
A16: 15 | B16: בּוֹלָנְדָא | C16: פולין
A17: 16 | B17: רֵיחָה | C17: ריח
A18: 17 | B18: לָחָד מָא | C18: עד ש
A19: 18 | B19: אָבָּדָן | C19: אף פעם
A20: 19 | B20: דָמְיָאן | C20: תמיד
A21: 20 | B21: צֻ'הֹר | C21: צהריים
A22: 21 | B22: בָּעֵד אְלצֻ'הֹר | C22: אחר הצהריים
A23: 22 | B23: לִסָּא | C23: עדיין
A24: 23 | B24: בְּרִטָאנְיָה | C24: אנגליה
A25: 24 | B25: נָאקֵס | C25: חסר
A26: 25 | B26: גָ'אהֵז | C26: מוכן

Sheet פעלים - שורשים
A1: מפתח | B1: שורש | C1: שם הפועל בעברית
A2: 1 | B2: זור | C2: לבקר
A3: 2 | B3: קול | C3: להגיד
A4: 3 | B4: שוף | C4: לראות
A5: 4 | B5: כון | C5: להיות
A6: 5 | B6: רוח | C6: ללכת
A7: 6 | B7: פות | C7: להיכנס
A8: 7 | B8: קום | C8: לקום
A9: 8 | B9: ציר | C9: להפוך ל
A10: 9 | B10: ג'יב | C10: להביא
A11: 10 | B11: פהם | C11: להבין
A12: 11 | B12: סמע | C12: לשמוע
A13: 12 | B13: פתח | C13: לפתוח
... A34: 33 | B34: נזל | C34: לוותר
A35: 34 | B35: עמל | C35: להשתמש | D35: 10
A36: 35 | B36: נסכּ | C36: להיתפס
A37: 36 | B37: כתב | C37: לכתוב
A38: 37 | B38: פחץ | C38: לבדוק
A39: 38 | B39: נדף | C39: לנקות
A40: 39 | B40: בדל | C40: להחליף
A41: 40 | B41: ע'יר | C41: להחליף
A42: 41 | B42: עיר | C42: לכוון
A43: 42 | B43: דח'ל | C43: להיכנס
A44: 43 | B44: קעד | C44: לשבת
A45: 44 | B45: טבח' | C45: לבשל
A46: 45 | B46: טלב | C46: לבקש
A47: 46 | B47: טלע | C47: להסתכל
A48: 47 | B48: דרס | C48: ללמוד
A49: 48 | B49: עמל | C49: לעשות | D49: 1
A50: 49 | B50: עזף | C50: לנגן
A51: 50 | B51: זבט | C51: להסתדר
A52: 51 | B52: בקי? | C52: להישאר
A53: 52 | B53: רמא? | C53: לזרוק
A54: 53 | B54: ח'לץ? | C54: להסתיים
A55: 54 | B55: ג'אי? | C55: לבוא
A56: 55 | B56: נסי? | C56: לשכוח
A57: 56 | B57: ? | C57: ליפול
A58: 57 | B58: ? | C58: לשבור
A59: 58 | B59: רוק? | C59: להירגע
A60: 59 | B60: הדי? | C60: להירגע
...

Sheet בינוני-פועל
B1: שורש (מפתח) | C1: שורש | D1: שם הפועל בעברית | E1: אני | F1: אתה | G1: את | H1: הוא | I1: היא | J1: אנחנו | K1: אתם/ן | L1: הם/ן
A2: 1 | B2: 32 | C2: =VLOOKUP($B$2,'פעלים - שורשים'!$A:$T,2,FALSE) -> ספר | D2: =VLOOKUP($B$2,'פעלים - שורשים'!$A:$T,3,FALSE) -> לנסוע | E2: מְסָאפֵר | F2: מְסָאפֵר | G2: מְסָאפְרֵה | H2: מְסָאפֵר | I2: מְסָאפְרֵה | J2: מְסָאפְרִין | K2: מְסָאפְרִין | L2: מְסָאפְרִין

Sheet הווה-עתיד
A1: שורש (מפתח) | B1: שורש | C1: בניין | D1: גזרה | E1: שם הפועל בעברית | F1: אני | G1: אתה | H1: את | I1: הוא | J1: היא | K1: אנחנו | L1: אתם/ן | M1: הם/ן
A2: 1 | B2: =VLOOKUP(A2,'פעלים - שורשים'!A:C,2,FALSE) -> זור | C2: 1 | D2: עוי | E2: =VLOOKUP(A2,'פעלים - שורשים'!A:C,3,FALSE) -> לבקר | F2: בָּזוּר | G2: בִּתְזוּר | H2: בִּתְזוּרִי | I2: בִּזוּר | J2: בִּתְזוּר | K2: בִּנְזוּר | L2: בִּתְזוּרוּ | M2: בִּזוּרוּ
A3: 2 | B3: =VLOOKUP(A3,'פעלים - שורשים'!A:C,2,FALSE) -> קול | C3: 1 | D3: עוי | E3: =VLOOKUP(A3,'פעלים - שורשים'!A:C,3,FALSE) -> להגיד | F3: בָּקוּל | G3: בִּתְקוּל | H3: בִּתְקוּלִי | I3: בִּקוּל | J3: בִּתְקוּל | K3: בִּנְקוּל | L3: בִּתְקוּלוּ | M3: בִּקוּלוּ
A4: 3 | B4: =VLOOKUP(A4,'פעלים - שורשים'!A:C,2,FALSE) -> שוף | C4: 1 | D4: עוי | E4: =VLOOKUP(A4,'פעלים - שורשים'!A:C,3,FALSE) -> לראות | F4: בָּשוּף | G4: בִּתְשוּף | H4: בִּתְשוּפִי | I4: בִּשוּף | J4: בִּתְשוּף | K4: בִּנְשוּף | L4: בִּתְשוּפוּ | M4: בִּשוּפוּ
A5: 4 | B5: =VLOOKUP(A5,'פעלים - שורשים'!A:C,2,FALSE) -> כון | C5: 1 | D5: עוי | E5: =VLOOKUP(A5,'פעלים - שורשים'!A:C,3,FALSE) -> להיות | F5: בָּכּוּן | G5: בִּתְכּוּן | H5: בִּתְכּוּנִי | I5: בִּכּוּן | J5: בִּתְכּוּן | K5: בִּנְכּוּן | L5: בִּתְכּוּנוּ | M5: בִּכּוּנוּ
A6: 5 | B6: =VLOOKUP(A6,'פעלים - שורשים'!A:C,2,FALSE) -> רוח | C6: 1 | D6: עוי | E6: =VLOOKUP(A6,'פעלים - שורשים'!A:C,3,FALSE) -> ללכת | F6: בָּרוּח | G6: בִּתְרוּח | H6: בִּתְרוּחִי | I6: בִּרוּח | J6: בִּתְרוּח | K6: בִּנְרוּח | L6: בִּתְרוּחוּ | M6: בִּרוּחוּ
A7: 6 | B7: =VLOOKUP(A7,'פעלים - שורשים'!A:C,2,FALSE) -> פות | C7: 1 | D7: עוי | E7: =VLOOKUP(A7,'פעלים - שורשים'!A:C,3,FALSE) -> להיכנס | F7: בָּפוּת | G7: בִּתְפוּת | H7: בִּתְפוּתִי | I7: בִּפוּת | J7: בִּתְפוּת | K7: בִּנְפוּת | L7: בִּתְפוּתוּ | M7: בִּפוּתוּ
A8: 7 | B8: =VLOOKUP(A8,'פעלים - שורשים'!A:C,2,FALSE) -> קום | C8: 1 | D8: עו"י | E8: =VLOOKUP(A8,'פעלים - שורשים'!A:C,3,FALSE) -> לקום | F8: בָּקוּם | G8: בִּתְקוּם | H8: בִּתְקוּמִי | I8: בִּקוּם | J8: בִּתְקוּם | K8: בִּנְקוּם | L8: בִּתְקוּמוּ | M8: בִּקוּמוּ
A9: 8 | B9: =VLOOKUP(A9,'פעלים - שורשים'!A:C,2,FALSE) -> ציר | C9: 1 | D9: עו"י | E9: =VLOOKUP(A9,'פעלים - שורשים'!A:C,3,FALSE) -> להפוך ל | F9: בָּצִיר | G9: בִּתְצִיר | H9: בִּתְצִירִי | I9: בִּצִיר | J9: בִּתְצִיר | K9: בִּנְצִיר | L9: בִּתְצִירוּ | M9: בִּצִירוּ
A10: 9 | B10: =VLOOKUP(A10,'פעלים - שורשים'!A:C,2,FALSE) -> ג'יב | C10: 1 | D10: עו"י | E10: =VLOOKUP(A10,'פעלים - שורשים'!A:C,3,FALSE) -> להביא | F10: בָּגִ'יבּ | G10: בִּתְגִ'יבּ | H10: בִּתְגִ'יבִּי | I10: בִּגִ'יבּ | J10: בִּתְגִ'יבּ | K10: בִּנְגִ'יבּ | L10: בִּתְגִ'יבּוּ | M10: בִּגִ'יבּוּ
A11: 10 | B11: =VLOOKUP(A11,'פעלים - שורשים'!A:C,2,FALSE) -> פהם | C11: 1 | D11: שלמים | E11: =VLOOKUP(A11,'פעלים - שורשים'!A:C,3,FALSE) -> להבין | F11: בָּפְהָם | G11: בְּתִפְהָם | H11: בְּתִפְהָמִי | I11: בִּפְהָם | J11: בְּתִפְהָם | K11: בְּנִפְהָם | L11: בְּתִפְהָמוּ | M11: בִּפְהָמוּ
A12: 11 | B12: =VLOOKUP(A12,'פעלים - שורשים'!A:C,2,FALSE) -> סמע | C12: 1 | D12: שלמים | E12: =VLOOKUP(A12,'פעלים - שורשים'!A:C,3,FALSE) -> לשמוע | F12: בָּסְמָע | G12: בְּתִסְמָע | H12: בְּתִסְמָעִי | I12: בִּסְמָע | J12: בְּתִסְמָע | K12: בְּנִסְמָע | L12: בְּתִסְמָעוּ | M12: בִּסְמָעוּ
A13: 12 | B13: =VLOOKUP(A13,'פעלים - שורשים'!A:C,2,FALSE) -> פתח | C13: 1 | D13: שלמים | E13: =VLOOKUP(A13,'פעלים - שורשים'!A:C,3,FALSE) -> לפתוח | F13: בָּפְתָח | G13: בְּתִפְתָח | H13: בְּתִפְתָחִי | I13: בִּפְתָח | J13: בְּתִפְתָח | K13: בְּנִפְתָח | L13: בְּתִפְתָחוּ | M13: בִּפְתָחוּ
... A23: 22 | B23: =VLOOKUP(A23,'פעלים - שורשים'!A:C,2,FALSE) -> בכי | C23: 1 | D23: לו"י | E23: =VLOOKUP(A23,'פעלים - שורשים'!A:C,3,FALSE) -> לבכות | F23: בָּבְּכִּי | G23: בְּתִבְּכִּי | H23: בְּתִבְּכִּי | I23: בִּבְּכִּי | J23: בְּתִבְּכִּי | K23: בְּנִבְּכִּי | L23: בְּתִבְּכּוּ | M23: בִּבְּכּוּ
A24: 23 | B24: =VLOOKUP(A24,'פעלים - שורשים'!A:C,2,FALSE) -> עלם | C24: 5 | E24: =VLOOKUP(A24,'פעלים - שורשים'!A:C,3,FALSE) -> ללמוד | F24: בָּתְעָלָם | G24: בְּתִתְעָלָם | H24: בְּתִתְעָלָמִי | I24: בִּתְעָלָם | J24: בְּתִתְעָלָם | K24: בְּנִתְעָלָם | L24: בְּתִתְעָלָמוּ | M24: בִּתְעָלָמוּ
A25: 24 | B25: =VLOOKUP(A25,'פעלים - שורשים'!A:C,2,FALSE) -> אחר | C25: 5 | E25: =VLOOKUP(A25,'פעלים - שורשים'!A:C,3,FALSE) -> לאחר | F25: בָּתְאָחָר | G25: בְּתִתְאָחָ'ר | H25: בְּתִתְאָחָרִי | I25: בִּתְאָחָר | J25: בְּתִתְאָחָר | K25: בְּנִתְאָחָר | L25: בְּתִתְאָחָרוּ | M25: בִּתְאָחָרוּ
A26: 25 | B26: =VLOOKUP(A26,'פעלים - שורשים'!A:C,2,FALSE) -> אמל | C26: 5 | E26: =VLOOKUP(A26,'פעלים - שורשים'!A:C,3,FALSE) -> לקוות | F26: בָּתְאָמָל | G26: בְּתִתְאָמָל | H26: בְּתִתְאָמָלִי | I26: בִּתְאָמָל | J26: בְּתִתְאָמָל | K26: בְּנִתְאָמָל | L26: בְּתִתְאָמָלוּ | M26: בִּתְאָמָלוּ
A27: 26 | B27: =VLOOKUP(A27,'פעלים - שורשים'!A:C,2,FALSE) -> עוד | C27: 5 | E27: =VLOOKUP(A27,'פעלים - שורשים'!A:C,3,FALSE) -> להתרגל | F27: בָּתְעָוָד | G27: בְּתִתְעָוָד | H27: בְּתִתְעָוָדִי | I27: בִּתְעָוָד | J27: בְּתִתְעָוָד | K27: בְּנִתְעָוָד | L27: בְּתִתְעָוָדוּ | M27: בִּתְעָוָדוּ
A28: 27 | B28: =VLOOKUP(A28,'פעלים - שורשים'!A:C,2,FALSE) -> שע'ל | C28: 8 | E28: =VLOOKUP(A28,'פעלים - שורשים'!A:C,3,FALSE) -> לעבוד | F28: בָּשְתְעֵ'ל | G28: בְּתִשְתְעֵ'ל | H28: בְּתִשְתְעֵ'לִי | I28: בִּשְתְעֵ'ל | J28: בְּתִשְתְעֵ'ל | K28: בְּנִשְתְעֵ'ל | L28: בְּתִשְתְעֵ'לוּ | M28: בִּשְתְעֵ'לוּ
A29: 28 | B29: =VLOOKUP(A29,'פעלים - שורשים'!A:C,2,FALSE) -> ג'מע | C29: 8 | E29: =VLOOKUP(A29,'פעלים - שורשים'!A:C,3,FALSE) -> להיפגש | F29: בָּגְ'תְמֵע | G29: בְּתִגְ'תְמֵע | H29: בְּתִגְ'תְמֵעִי | I29: בִּגְ'תְמֵע | J29: בְּתִגְ'תְמֵע | K29: בְּנִגְ'תְמֵע | L29: בְּתִגְ'תְמֵעוּ | M29: בִּגְ'תְמֵעוּ
A30: 29 | B30: =VLOOKUP(A30,'פעלים - שורשים'!A:C,2,FALSE) -> שרכּ | C30: 8 | E30: =VLOOKUP(A30,'פעלים - שורשים'!A:C,3,FALSE) -> להשתתף | F30: בָּשְתְרֵכּ | G30: בְּתִשְתְרֵכּ | H30: בְּתִשְתְרֵכִּי | I30: בִּשְתְרֵכּ | J30: בְּתִשְתְרֵכּ | K30: בְּנִשְתְרֵכּ | L30: בְּתִשְתְרֵכּוּ | M30: בִּשְתְרֵכּוּ
A31: 30 | B31: =VLOOKUP(A31,'פעלים - שורשים'!A:C,2,FALSE) -> סלם | C31: 8 | E31: =VLOOKUP(A31,'פעלים - שורשים'!A:C,3,FALSE) -> לקבל | F31: בָּסְתְלֵם | G31: בְּתִסְתְלֵם | H31: בְּתִסְתְלֵמִי | I31: בִּסְתְלֵם | J31: בְּתִסְתְלֵם | K31: בְּנִסְתְלֵם | L31: בְּתִסְתְלֵמוּ | M31: בִּסְתְלֵמוּ
A32: 31 | B32: =VLOOKUP(A32,'פעלים - שורשים'!A:C,2,FALSE) -> קרר | C32: 2 | E32: =VLOOKUP(A32,'פעלים - שורשים'!A:C,3,FALSE) -> להחליט | F32: בָּקְרֵר | G32: בִּתְקָרֵר | H32: בִּתְקָרֵרִי | I32: בִּקָרֵר | J32: בִּתְקָרֵר | K32: בִּנְקָרֵר | L32: בִּתְקָרֵרוּ | M32: בִּקָרֵרוּ
A33: 32 | B33: =VLOOKUP(A33,'פעלים - שורשים'!A:C,2,FALSE) -> ספר | C33: 3 | E33: =VLOOKUP(A33,'פעלים - שורשים'!A:C,3,FALSE) -> לנסוע | F33: בָּסָאפֵר | G33: בִּתְסָאפֵר | H33: בִּתְסָאפֵרִי | I33: בִּסָאפֵר | J33: בִּתְסָאפֵר | K33: בִּנְסָאפֵר | L33: בִּתְסָאפֵרוּ | M33: בִּסָאפֵרוּ
A34: 33 | B34: =VLOOKUP(A34,'פעלים - שורשים'!A:C,2,FALSE) -> נזל | C34: 6 | E34: =VLOOKUP(A34,'פעלים - שורשים'!A:C,3,FALSE) -> לוותר | F34: בָּתְנָאזָל | G34: בְּתִתְנָאזָל | H34: בְּתִתְנָאזָלִי | I34: בִּתְנָאזָל | J34: בְּתִתְנָאזָל | K34: בְּנִתְנָאזָל | L34: בְּתִתְנָאזָלוּ | M34: בִּתְנָאזָלוּ
A35: 34 | B35: =VLOOKUP(A35,'פעלים - שורשים'!A:C,2,FALSE) -> עמל | C35: 10 | E35: =VLOOKUP(A35,'פעלים - שורשים'!A:C,3,FALSE) -> להשתמש | F35: בָּסְתָעְמֵל | G35: בְּתִסְתָעְמֵל | H35: בְּתִסְתָעְמֵלִי | I35: בִּסְתָעְמֵל | J35: בְּתִסְתָעְמֵל | K35: בְּנִסְתָעְמֵל | L35: בְּתִסְתָעְמֵלוּ | M35: בִּסְתָעְמֵלוּ
A36: 35 | B36: =VLOOKUP(A36,'פעלים - שורשים'!A:C,2,FALSE) -> נסכּ | C36: 7 | E36: =VLOOKUP(A36,'פעלים - שורשים'!A:C,3,FALSE) -> להיתפס | F36: בָּנִמְסֵכּ | G36: בְּתִנִמְסֵכּ | H36: בְּתִנִמְסֵכִּי | I36: בִּנִמְסֵכּ | J36: בְּתִנִמְסֵכּ | K36: בְּנִנִמְסֵכּ | L36: בְּתִנִמְסֵכּוּ | M36: בִּנִמְסֵכּוּ
A37: 36 | B37: =VLOOKUP(A37,'פעלים - שורשים'!A:C,2,FALSE) -> כתב | C37: 1 | D37: שלמים | E37: =VLOOKUP(A37,'פעלים - שורשים'!A:C,3,FALSE) -> לכתוב | F37: בָּכְּתֹבּ | G37: בְּתֻכְּתֹבּ | H37: בְּתֻכֻּתֹבִּי | I37: בֻּכְּתֹבּ | J37: בְּתֻכְּתֹבּ | K37: בְּנֻכְּתֹבּ | L37: בְּתֻכֻּתֹבּוּ | M37: בֻּכֻּתֹבּוּ
A38: 37 | B38: =VLOOKUP(A38,'פעלים - שורשים'!A:C,2,FALSE) -> פחץ | E38: =VLOOKUP(A38,'פעלים - שורשים'!A:C,3,FALSE) -> לבדוק | F38: בָּפְחָץ | G38: בְּתִפְחָץ | H38: בְּתִפְחָצִי | I38: בִּפְחָץ | J38: בְּתִפְחָץ | K38: בְּנִפְחָץ | L38: בְּתִפְחָצוּ | M38: בִּפְחָצוּ
A39: 38 | B39: =VLOOKUP(A39,'פעלים - שורשים'!A:C,2,FALSE) -> נדף | E39: =VLOOKUP(A39,'פעלים - שורשים'!A:C,3,FALSE) -> לנקות | F39: בָּנָדֵף | G39: בִּתְנָדֵף | H39: בִּתְנָדְפִי | I39: בִּנָדֵף | J39: בִּתְנָדֵף | K39: בִּנָּדֵף | L39: בִּתְנָדְפוּ | M39: בִּנָדְפוּ
A40: 39 | B40: =VLOOKUP(A40,'פעלים - שורשים'!A:C,2,FALSE) -> בדל | E40: =VLOOKUP(A40,'פעלים - שורשים'!A:C,3,FALSE) -> להחליף | F40: בָּבָּדֵל | G40: בִּתְבָּדֵל | H40: בִּתְבָּדְלִי | I40: בִּבָּדֵל | J40: בִּתְבָּדֵל | K40: בִּנְבָּדֵל | L40: בִּתְבָּדְלוּ | M40: בִּבָּדְלוּ
A41: 40 | B41: =VLOOKUP(A41,'פעלים - שורשים'!A:C,2,FALSE) -> ע'יר | E41: =VLOOKUP(A41,'פעלים - שורשים'!A:C,3,FALSE) -> להחליף | F41: בָּעָ'יֵר | G41: בִּתְעָ'יֵר | H41: בִּתְעָ'יֵרִי | I41: בִּעָ'יֵר | J41: בִּתְעָ'יֵר | K41: בִּנְעָ'יֵר | L41: בִּתְעָ'יֵרוּ | M41: בִּעָ'יֵרוּ
A42: 41 | B42: =VLOOKUP(A42,'פעלים - שורשים'!A:C,2,FALSE) -> עיר | E42: =VLOOKUP(A42,'פעלים - שורשים'!A:C,3,FALSE) -> לכוון | F42: בָּעָיֵר | G42: בִּתְעָיֵר | H42: בִּתְעָיֵרִי | I42: בִּעָיֵר | J42: בִּתְעָיֵר | K42: בִּנְעָיֵר | L42: בִּתְעָיֵרוּ | M42: בִּעָיֵרוּ
A43: 42 | B43: =VLOOKUP(A43,'פעלים - שורשים'!A:C,2,FALSE) -> דח'ל | C43: 1 | D43: שלמים | E43: =VLOOKUP(A43,'פעלים - שורשים'!A:C,3,FALSE) -> להיכנס | F43: בָּדְח'ֹל | G43: בְּתֻדְח'ֹל | H43: בְּתֻדֻח'ֹלִי | I43: בֻּדְח'ֹל | J43: בְּתֻדְח'ֹל | K43: בְּנֻדְח'ֹל | L43: בְּתֻדֻח'ֹלוּ | M43: בֻּדֻח'ֹלוּ
A44: 43 | B44: =VLOOKUP(A44,'פעלים - שורשים'!A:C,2,FALSE) -> קעד | C44: 1 | D44: שלמים | E44: =VLOOKUP(A44,'פעלים - שורשים'!A:C,3,FALSE) -> לשבת | F44: בָּקְעֹד | G44: בְּתֻקְעֹד | H44: בְּתֻקֻעְדִי | I44: בֻּקְעֹד | J44: בְּתֻקְעֹד | K44: בְּנֻקְעֹד | L44: בְּתֻקֻעְדוּ | M44: בֻּקֻעְדוּ
A45: 44 | B45: =VLOOKUP(A45,'פעלים - שורשים'!A:C,2,FALSE) -> טבח' | C45: 1 | D45: שלמים | E45: =VLOOKUP(A45,'פעלים - שורשים'!A:C,3,FALSE) -> לבשל | F45: בָּטְבֹּח' | G45: בְּתֻטְבֹּח' | H45: בְּתֻטֻבְּחִ'י | I45: בֻּטְבֹּח' | J45: בְּתֻטְבֹּח' | K45: בְּנֻטְבֹּח' | L45: בְּתֻטֻבְּח'וּ | M45: בֻּטֻבְּח'וּ
A46: 45 | B46: =VLOOKUP(A46,'פעלים - שורשים'!A:C,2,FALSE) -> טלב | C46: 1 | D46: שלמים | E46: =VLOOKUP(A46,'פעלים - שורשים'!A:C,3,FALSE) -> לבקש | F46: בָּטְלֹבּ | G46: בְּתֻטְלֹבּ | H46: בְּתֻטֻלְבִּי | I46: בֻּטְלֹבּ | J46: בְּתֻטְלֹבּ | K46: בְּנֻטְלֹבּ | L46: בְּתֻטֻלְבּוּ | M46: בֻּטֻלְבּוּ
A47: 48 | B47: =VLOOKUP(A47,'פעלים - שורשים'!A:C,2,FALSE) -> עמל | E47: =VLOOKUP(A47,'פעלים - שורשים'!A:C,3,FALSE) -> לעשות | F47: בָּעְמֵל | G47: בְּתִעְמֵל | H47: בְּתִעִמְלִי | I47: בִּעְמֵל | J47: בְּתִעְמֵל | K47: בְּנִעְמֵל | L47: בְּתִעִמְלוּ | M47: בִּעִמְלוּ
A48: 46 | B48: =VLOOKUP(A48,'פעלים - שורשים'!A:C,2,FALSE) -> טלע | C48: 5 | E48: =VLOOKUP(A48,'פעלים - שורשים'!A:C,3,FALSE) -> להסתכל
A49: 47 | B49: =VLOOKUP(A49,'פעלים - שורשים'!A:C,2,FALSE) -> דרס | E49: =VLOOKUP(A49,'פעלים - שורשים'!A:C,3,FALSE) -> ללמוד | F49: בָּדְרֹס | G49: בְּתֻדְרֹס | H49: בְּתֻדֻרְסִי | I49: בֻּדְרֹס | J49: בְּתֻדְרֹס | K49: בְּנֻדְרֹס | L49: בְּתֻדֻרְסוּ | M49: בֻּדֻרְסוּ
...

Sheet עבר
A1: שורש (מפתח) | B1: שורש | C1: שם הפועל בעברית | D1: אני | E1: אתה | F1: את | G1: הוא | H1: היא | I1: אנחנו | J1: אתם/ן | K1: הם/ן
A2: 3 | B2: =VLOOKUP(A2,'פעלים - שורשים'!A:C,2,FALSE) -> שוף | C2: =VLOOKUP(A2,'פעלים - שורשים'!A:C,3,FALSE) -> לראות | D2: שֻפְת | E2: שֻפְת | F2: שֻפְתִי | G2: שָאף | H2: שָאפָה | I2: שֻפְנָא | J2: שֻפְתוּ | K2: שָאפוּ
A3: 4 | B3: =VLOOKUP(A3,'פעלים - שורשים'!A:C,2,FALSE) -> כון | C3: =VLOOKUP(A3,'פעלים - שורשים'!A:C,3,FALSE) -> להיות | D3: כֻּנְת | E3: כֻּנְת | F3: כֻּנְתִי | G3: כָּאן | H3: כָּאנָת | I3: כֻּנָא | J3: כֻּנְתוּ | K3: כָּאנוּ
A4: 9 | B4: =VLOOKUP(A4,'פעלים - שורשים'!A:C,2,FALSE) -> ג'יב | C4: =VLOOKUP(A4,'פעלים - שורשים'!A:C,3,FALSE) -> להביא | D4: גִ'בְּת | E4: גִ'בְּת | F4: גִ'בְּתִי | G4: גָ'אבּ | H4: גָ'אבָּת | I4: גִ'בְּנָא | J4: גִ'בְּתוּ | K4: גָ'אבּוּ
A5: 47 | B5: =VLOOKUP(A5,'פעלים - שורשים'!A:C,2,FALSE) -> דרס | C5: =VLOOKUP(A5,'פעלים - שורשים'!A:C,3,FALSE) -> ללמוד | G5: דָרָס | H5: דָרָסָת | K5: דָרָסוּ
A6: 52 | B6: =VLOOKUP(A6,'פעלים - שורשים'!A:C,2,FALSE) -> רמא? | C6: =VLOOKUP(A6,'פעלים - שורשים'!A:C,3,FALSE) -> לזרוק | G6: רָמָא
A7: 53 | B7: =VLOOKUP(A7,'פעלים - שורשים'!A:C,2,FALSE) -> ח'לץ? | C7: =VLOOKUP(A7,'פעלים - שורשים'!A:C,3,FALSE) -> להסתיים | G7: חָ'לָץ
A8: 51 | B8: =VLOOKUP(A8,'פעלים - שורשים'!A:C,2,FALSE) -> בקי? | C8: =VLOOKUP(A8,'פעלים - שורשים'!A:C,3,FALSE) -> להישאר | G8: בָּקָא
A9: 54 | B9: =VLOOKUP(A9,'פעלים - שורשים'!A:C,2,FALSE) -> ג'אי? | C9: =VLOOKUP(A9,'פעלים - שורשים'!A:C,3,FALSE) -> לבוא | G9: אָגָ'א | H9: אָגָ'ת
A10: 55 | B10: =VLOOKUP(A10,'פעלים - שורשים'!A:C,2,FALSE) -> נסי? | C10: =VLOOKUP(A10,'פעלים - שורשים'!A:C,3,FALSE) -> לשכוח | G10: נִסִי
A11: 56 | B11: =VLOOKUP(A11,'פעלים - שורשים'!A:C,2,FALSE) -> ? | C11: =VLOOKUP(A11,'פעלים - שורשים'!A:C,3,FALSE) -> ליפול | H11: וִקְעָת
A12: 57 | B12: =VLOOKUP(A12,'פעלים - שורשים'!A:C,2,FALSE) -> ? | C12: =VLOOKUP(A12,'פעלים - שורשים'!A:C,3,FALSE) -> לשבור | H12: כָּסְרָת
A13: 63 | B13: =VLOOKUP(A13,'פעלים - שורשים'!A:C,2,FALSE) -> סעד? | C13: =VLOOKUP(A13,'פעלים - שורשים'!A:C,3,FALSE) -> לעזור | G13: סָאעָד

Sheet ציווי
A1: שורש (מפתח) | B1: שורש | C1: שם הפועל בעברית | D1: אתה | E1: את | F1: אתם/ן
A2: 3 | B2: =VLOOKUP(A2,'פעלים - שורשים'!A:C,2,FALSE) -> שוף | C2: =VLOOKUP(A2,'פעלים - שורשים'!A:C,3,FALSE) -> לראות | D2: שֻפְ | E2: שֻפִי | F2: שֻפוּ
A3: 58 | B3: =VLOOKUP(A3,'פעלים - שורשים'!A:C,2,FALSE) -> רוק? | C3: =VLOOKUP(A3,'פעלים - שורשים'!A:C,3,FALSE) -> להירגע | D3: רוּק | E3: רוּקִי? | F3: רוּקוּ?
A4: 59 | B4: =VLOOKUP(A4,'פעלים - שורשים'!A:C,2,FALSE) -> הדי? | C4: =VLOOKUP(A4,'פעלים - שורשים'!A:C,3,FALSE) -> להירגע | D4: אִהְדָא | E4: אִהְדִי | F4: אִהְדוּ?
A5: 60 | B5: =VLOOKUP(A5,'פעלים - שורשים'!A:C,2,FALSE) -> ? | C5: =VLOOKUP(A5,'פעלים - שורשים'!A:C,3,FALSE) -> לקרוא | D5: נָאדִי | E5: נָאדִי? | F5: נָאדוּ?
A6: 55 | B6: =VLOOKUP(A6,'פעלים - שורשים'!A:C,2,FALSE) -> נסי? | C6: =VLOOKUP(A6,'פעלים - שורשים'!A:C,3,FALSE) -> לשכוח | D6: אִנְסָא | E6: אִנְסִי | F6: אִנְסוּ?
A7: 62 | B7: =VLOOKUP(A7,'פעלים - שורשים'!A:C,2,FALSE) -> חוד? | C7: =VLOOKUP(A7,'פעלים - שורשים'!A:C,3,FALSE) -> לקחת | D7: חֻ'ד | E7: חֻ'דִי | F7: חֻ'דוּ
